Traceback (most recent call last):
  File "/opt/hostedtoolcache/Python/3.11.10/x64/lib/python3.11/site-packages/jupyter_cache/executors/utils.py", line 58, in single_nb_execution
    executenb(
  File "/opt/hostedtoolcache/Python/3.11.10/x64/lib/python3.11/site-packages/nbclient/client.py", line 1314, in execute
    return NotebookClient(nb=nb, resources=resources, km=km, **kwargs).execute()
           ^^^^^^^^^^^^^^^^^^^^^^^^^^^^^^^^^^^^^^^^^^^^^^^^^^^^^^^^^^^^^^^^^^^^^
  File "/opt/hostedtoolcache/Python/3.11.10/x64/lib/python3.11/site-packages/jupyter_core/utils/__init__.py", line 165, in wrapped
    return loop.run_until_complete(inner)
           ^^^^^^^^^^^^^^^^^^^^^^^^^^^^^^
  File "/opt/hostedtoolcache/Python/3.11.10/x64/lib/python3.11/asyncio/base_events.py", line 654, in run_until_complete
    return future.result()
           ^^^^^^^^^^^^^^^
  File "/opt/hostedtoolcache/Python/3.11.10/x64/lib/python3.11/site-packages/nbclient/client.py", line 709, in async_execute
    await self.async_execute_cell(
  File "/opt/hostedtoolcache/Python/3.11.10/x64/lib/python3.11/site-packages/nbclient/client.py", line 1062, in async_execute_cell
    await self._check_raise_for_error(cell, cell_index, exec_reply)
  File "/opt/hostedtoolcache/Python/3.11.10/x64/lib/python3.11/site-packages/nbclient/client.py", line 918, in _check_raise_for_error
    raise CellExecutionError.from_cell_and_msg(cell, exec_reply_content)
nbclient.exceptions.CellExecutionError: An error occurred while executing the following cell:
------------------
# Initialize ResourceManager
rm = ResourceManager()
docs_resources = rm.get_path("docs_resources", "vasca")
gal_visits = rm.get_path("gal_visits_list", "vasca")
------------------


[0;31m---------------------------------------------------------------------------[0m
[0;31mValueError[0m                                Traceback (most recent call last)
Cell [0;32mIn[4], line 3[0m
[1;32m      1[0m [38;5;66;03m# Initialize ResourceManager[39;00m
[1;32m      2[0m rm [38;5;241m=[39m ResourceManager()
[0;32m----> 3[0m docs_resources [38;5;241m=[39m [43mrm[49m[38;5;241;43m.[39;49m[43mget_path[49m[43m([49m[38;5;124;43m"[39;49m[38;5;124;43mdocs_resources[39;49m[38;5;124;43m"[39;49m[43m,[49m[43m [49m[38;5;124;43m"[39;49m[38;5;124;43mvasca[39;49m[38;5;124;43m"[39;49m[43m)[49m
[1;32m      4[0m gal_visits [38;5;241m=[39m rm[38;5;241m.[39mget_path([38;5;124m"[39m[38;5;124mgal_visits_list[39m[38;5;124m"[39m, [38;5;124m"[39m[38;5;124mvasca[39m[38;5;124m"[39m)

File [0;32m/opt/hostedtoolcache/Python/3.11.10/x64/lib/python3.11/site-packages/vasca/resource_manager.py:380[0m, in [0;36mResourceManager.get_path[0;34m(self, resource, storage)[0m
[1;32m    378[0m     [38;5;28;01mraise[39;00m [38;5;167;01mValueError[39;00m([38;5;124m"[39m[38;5;124mNot a file at [39m[38;5;124m'[39m[38;5;132;01m{}[39;00m[38;5;124m'[39m[38;5;124m"[39m[38;5;241m.[39mformat(path))
[1;32m    379[0m [38;5;28;01melif[39;00m resource_type [38;5;241m==[39m [38;5;124m"[39m[38;5;124mdirectory[39m[38;5;124m"[39m [38;5;129;01mand[39;00m [38;5;129;01mnot[39;00m os[38;5;241m.[39mpath[38;5;241m.[39misdir(path):
[0;32m--> 380[0m     [38;5;28;01mraise[39;00m [38;5;167;01mValueError[39;00m([38;5;124m"[39m[38;5;124mNot a directory at [39m[38;5;124m'[39m[38;5;132;01m{}[39;00m[38;5;124m'[39m[38;5;124m"[39m[38;5;241m.[39mformat(path))
[1;32m    382[0m [38;5;66;03m# success message if verbose[39;00m
[1;32m    383[0m [38;5;28;01mif[39;00m [38;5;28mself[39m[38;5;241m.[39mflags[[38;5;124m"[39m[38;5;124mverbose[39m[38;5;124m"[39m]:

[0;31mValueError[0m: Not a directory at '/home/runner/work/vasca/vasca/docs/tutorial_resources'

