Traceback (most recent call last):
  File "/opt/hostedtoolcache/Python/3.11.10/x64/lib/python3.11/site-packages/jupyter_cache/executors/utils.py", line 58, in single_nb_execution
    executenb(
  File "/opt/hostedtoolcache/Python/3.11.10/x64/lib/python3.11/site-packages/nbclient/client.py", line 1314, in execute
    return NotebookClient(nb=nb, resources=resources, km=km, **kwargs).execute()
           ^^^^^^^^^^^^^^^^^^^^^^^^^^^^^^^^^^^^^^^^^^^^^^^^^^^^^^^^^^^^^^^^^^^^^
  File "/opt/hostedtoolcache/Python/3.11.10/x64/lib/python3.11/site-packages/jupyter_core/utils/__init__.py", line 165, in wrapped
    return loop.run_until_complete(inner)
           ^^^^^^^^^^^^^^^^^^^^^^^^^^^^^^
  File "/opt/hostedtoolcache/Python/3.11.10/x64/lib/python3.11/asyncio/base_events.py", line 654, in run_until_complete
    return future.result()
           ^^^^^^^^^^^^^^^
  File "/opt/hostedtoolcache/Python/3.11.10/x64/lib/python3.11/site-packages/nbclient/client.py", line 709, in async_execute
    await self.async_execute_cell(
  File "/opt/hostedtoolcache/Python/3.11.10/x64/lib/python3.11/site-packages/nbclient/client.py", line 1062, in async_execute_cell
    await self._check_raise_for_error(cell, cell_index, exec_reply)
  File "/opt/hostedtoolcache/Python/3.11.10/x64/lib/python3.11/site-packages/nbclient/client.py", line 918, in _check_raise_for_error
    raise CellExecutionError.from_cell_and_msg(cell, exec_reply_content)
nbclient.exceptions.CellExecutionError: An error occurred while executing the following cell:
------------------
rm = ResourceManager()
test_dir = rm.get_path("test_resources", "vasca")
[x.name for x in Path(test_dir).glob("*") if x.is_dir()]
------------------


[0;31m---------------------------------------------------------------------------[0m
[0;31mException[0m                                 Traceback (most recent call last)
Cell [0;32mIn[3], line 1[0m
[0;32m----> 1[0m rm [38;5;241m=[39m [43mResourceManager[49m[43m([49m[43m)[49m
[1;32m      2[0m test_dir [38;5;241m=[39m rm[38;5;241m.[39mget_path([38;5;124m"[39m[38;5;124mtest_resources[39m[38;5;124m"[39m, [38;5;124m"[39m[38;5;124mvasca[39m[38;5;124m"[39m)
[1;32m      3[0m [x[38;5;241m.[39mname [38;5;28;01mfor[39;00m x [38;5;129;01min[39;00m Path(test_dir)[38;5;241m.[39mglob([38;5;124m"[39m[38;5;124m*[39m[38;5;124m"[39m) [38;5;28;01mif[39;00m x[38;5;241m.[39mis_dir()]

File [0;32m/opt/hostedtoolcache/Python/3.11.10/x64/lib/python3.11/site-packages/vasca/resource_manager.py:68[0m, in [0;36mResourceManager.__init__[0;34m(self, verbose)[0m
[1;32m     65[0m [38;5;28mself[39m[38;5;241m.[39mmetadata [38;5;241m=[39m [38;5;28mself[39m[38;5;241m.[39m_load_metadata()
[1;32m     67[0m [38;5;66;03m# set environment variables[39;00m
[0;32m---> 68[0m [38;5;28;43mself[39;49m[38;5;241;43m.[39;49m[43m_load_env[49m[43m([49m[43m)[49m

File [0;32m/opt/hostedtoolcache/Python/3.11.10/x64/lib/python3.11/site-packages/vasca/resource_manager.py:159[0m, in [0;36mResourceManager._load_env[0;34m(self, config_path, overwrite)[0m
[1;32m    157[0m [38;5;66;03m# raise error if no env var was previously set and config file is also missing[39;00m
[1;32m    158[0m [38;5;28;01melif[39;00m [38;5;129;01mnot[39;00m [38;5;28mall[39m(env_status_list) [38;5;129;01mand[39;00m [38;5;129;01mnot[39;00m found_config:
[0;32m--> 159[0m     [38;5;28;01mraise[39;00m [38;5;167;01mException[39;00m(
[1;32m    160[0m         [38;5;28mstr[39m[38;5;241m.[39mformat(
[1;32m    161[0m             [38;5;124m"[39m[38;5;124mUnable to set environemt variables [39m[38;5;132;01m{}[39;00m[38;5;124m. [39m[38;5;124m"[39m
[1;32m    162[0m             [38;5;124m"[39m[38;5;124mSolve it by adding them to the config file at [39m[38;5;124m'[39m[38;5;132;01m{}[39;00m[38;5;124m'[39m[38;5;124m [39m[38;5;124m"[39m
[1;32m    163[0m             [38;5;124m"[39m[38;5;124mor setting the variables manually in your shell config.[39m[38;5;124m"[39m,
[1;32m    164[0m             [
[1;32m    165[0m                 var
[1;32m    166[0m                 [38;5;28;01mfor[39;00m var [38;5;129;01min[39;00m [38;5;28mself[39m[38;5;241m.[39mmetadata[[38;5;124m"[39m[38;5;124menvs[39m[38;5;124m"[39m]
[1;32m    167[0m                 [38;5;28;01mif[39;00m [38;5;129;01mnot[39;00m [38;5;28mself[39m[38;5;241m.[39mmetadata[[38;5;124m"[39m[38;5;124menvs[39m[38;5;124m"[39m][var][[38;5;124m"[39m[38;5;124mset[39m[38;5;124m"[39m]
[1;32m    168[0m             ],
[1;32m    169[0m             config_path,
[1;32m    170[0m         )
[1;32m    171[0m     )
[1;32m    172[0m [38;5;66;03m# if not all env vars have been set previously but a config file exists[39;00m
[1;32m    173[0m [38;5;66;03m# missing env vars are replaced[39;00m
[1;32m    174[0m [38;5;28;01melif[39;00m [38;5;129;01mnot[39;00m [38;5;28mall[39m(env_status_list) [38;5;129;01mand[39;00m found_config:

[0;31mException[0m: Unable to set environemt variables ['VASCA_DEFAULT', 'UC_SAS_VASCARCAT', 'UC_LUSTRE_VASCARCAT']. Solve it by adding them to the config file at '/opt/hostedtoolcache/Python/3.11.10/x64/lib/python3.11/site-packages/vasca/../.env' or setting the variables manually in your shell config.

